test/100k_msg.txt
A,0,S,91,50.04
A,1,S,40,50.09
A,2,S,51,50.05
A,3,S,87,50.08
A,4,B,83,50.05
T,83,50.04
A,5,B,26,50.04
T,8,50.04
A,6,S,26,50.09
A,7,S,71,50.07
A,8,B,9,50.06
T,9,50.05
A,9,B,15,50.09
T,421,1006.01
T,15,50.05
A,10,B,1,50.05
T,1,50.05
X,1,S,40,50.09
A,11,B,13,50.06
T,13,50.05
A,12,B,58,50.06
T,13,50.05
A,13,B,96,50.11
T,71,50.07
T,25,50.08
A,14,B,97,50.09
T,62,50.08
T,26,50.09
A,15,S,97,50.03
T,9,50.03
T,45,50.03
T,18,50.03
A,16,S,48,50.07
A,17,B,30,50.03
T,25,50.03
X,17,B,5,50.03
A,18,S,14,50.12
A,19,S,67,50.10
A,20,B,11,50.03
A,21,S,100,50.09
A,22,B,89,50.07
T,48,50.07
A,23,S,70,50.10
A,24,S,51,50.14
A,25,B,17,50.08
M,0,B,10.83,976.00
A,26,S,30,50.11
A,27,B,6,50.09
A,19,S,29,1.573
T,6,50.09
A,28,S,54,50.12
A,29,B,45,50.11
T,45,50.09
A,30,S,18,50.14
X,19,S,67,50.10
A,31,S,36,50.13
A,32,B,5,50.12
T,5,50.09
A,33,S,88,50.10
A,34,B,45,50.11
T,44,50.09
T,1,50.10
A,35,B,37,50.13
T,37,50.10
A,36,S,29,50.15
A,37,B,59,50.12
T,32,50.10
T,27,50.10
A,38,S,53,50.11
A,39,B,29,50.13
T,29,50.10
X,31,S,36,50.13
X,18,S,14,50.12
A,40,S,37,50.15
M,0,S,10.45,597.00
A,41,B,12,50.12
T,12,50.10
A,42,S,59,50.13
A,43,B,17,50.10
T,17,50.10
A,44,S,80,50.11
A,45,S,18,50.15
A,46,S,49,50.14
A,47,S,11,50.12
A,48,B,45,50.11
T,3,50.10
T,30,50.11
T,12,50.11
A,49,S,20,50.14
A,50,B,60,50.12
T,41,50.11
T,19,50.11
A,51,S,42,50.15
A,52,S,14,50.13
A,53,S,3,50.16
M,28,S,105,50.12
A,54,S,67,50.14
X,25,B,17,50.08
A,55,B,11,50.08
A,56,S,84,50.15
X,3534,S,985,38.14
A,57,S,37,50.16
X,56,S,84,50.15
A,58,S,47,50.16
A,59,S,25,50.13
A,60,S,75,50.16
M,49,S,4,50.14
A,61,S,87,50.14
A,62,B,12,50.09
A,63,S,83,50.13
A,64,S,89,50.16
A,65,S,10,50.14
X,61,S,87,50.14
X,59,S,25,50.13
A,66,S,18,50.12
A,67,B,19,50.14
T,19,50.11
A,68,S,90,50.12
M,51,S,22,50.15
A,69,S,32,50.12
A,70,S,46,50.16
A,71,S,70,50.14
A,72,S,85,50.14
A,73,S,9,50.14
A,74,S,31,50.12
A,75,S,93,50.15
A,76,B,43,50.14
T,42,50.11
T,1,50.12
A,77,S,46,50.14
A,78,S,36,50.15
A,62,B,21,1.861
A,79,B,16,50.13
T,10,50.12
T,6,50.12
M,20,B,8,50.03
A,80,B,57,50.10
A,81,S,60,50.13
M,75,S,53,50.15
A,82,S,66,50.14
A,83,S,38,50.15
A,84,S,48,50.16
A,85,S,37,50.13
A,86,B,72,50.14
T,72,50.12
A,87,B,3,50.13
T,3,50.12
A,88,S,26,50.14
X,74,S,31,50.12
A,89,S,53,50.14
X,20,B,8,50.03
A,90,B,75,50.15
T,24,50.12
T,18,50.12
T,33,50.12
X,83,S,38,50.15
X,58,S,47,50.16
A,91,B,79,50.11
A,92,S,67,50.16
A,93,B,91,50.16
T,57,50.12
T,32,50.12
T,2,50.13
A,94,S,80,50.18
X,7529,B,518,4.22
M,63,S,38,50.13
A,95,B,44,50.13
A,24,S,10,1.358
T,44,50.13
X,70,S,46,50.16
A,96,S,4,50.18
A,97,B,63,50.14
T,13,50.13
T,14,50.13
T,36,50.13
A,98,S,68,50.16
A,99,B,27,50.15
T,2,50.13
T,25,50.13
M,80,B,36,50.10
A,100,S,86,50.16
M,94,S,24,50.18
M,94,S,15,50.18
A,101,S,97,50.18
A,102,S,3,50.14
A,103,B,49,50.12
M,22,B,12,50.07
A,104,B,75,50.14
T,35,50.13
T,37,50.13
T,3,50.14
A,105,S,90,50.17
A,pMKWPHqcnI,S,10,1234
A,106,S,3,50.18
M,22,B,15,50.07
A,107,B,62,50.13
X,57,S,37,50.16
M,55,B,16,50.08
A,108,S,30,50.18
M,80,B,54,50.10
M,45,S,31,50.15
A,109,S,87,50.13
T,62,50.13
A,110,B,44,50.17
T,25,50.13
T,19,50.14
A,111,B,60,50.16
T,29,50.14
T,18,50.14
T,13,50.14
A,112,B,8,50.17
T,8,50.14
A,113,S,63,50.16
A,114,S,65,50.18
A,115,S,60,50.16
X,51,S,22,50.15
A,116,B,42,50.17
T,28,50.14
T,4,50.14
T,10,50.14
A,117,B,5,50.13
T,916,9024.01
A,118,S,10,50.11
T,5,50.11
T,5,50.11
A,119,B,70,50.16
T,57,50.14
T,10,50.14
T,3,50.14
X,62,B,12,50.09
A,120,B,6,50.15
T,6,50.14
A,121,B,91,50.15
T,61,50.14
T,30,50.14
X,91,B,79,50.11
A,122,S,55,50.19
X,55,B,16,50.08
A,123,B,34,50.13
A,124,B,27,50.16
T,27,50.14
A,125,S,58,50.16
M,72,S,33,50.14
A,126,S,50,50.16
M,98,S,27,50.16
A,127,B,4,50.18
T,4,50.14
A,128,S,96,50.18
X,94,S,15,50.18
A,129,B,43,50.14
X,9952,S,394,19.79
T,5,50.14
T,38,50.14
A,130,B,84,50.14
T,8,50.14
T,66,50.14
T,10,50.14
A,131,B,58,50.18
T,16,50.14
T,42,50.14
X,84,S,48,50.16
A,132,S,82,50.16
A,133,B,14,50.18
T,11,50.14
T,3,50.14
A,134,S,23,50.19
M,80,B,97,50.10
A,135,S,78,50.19
A,136,S,84,50.16
A,137,B,43,50.15
T,33,50.14
T,10,50.15
X,75,S,53,50.15
A,138,S,30,50.16
X,123,B,34,50.13
A,139,B,42,50.16
T,19,50.15
T,23,50.15
X,22,B,15,50.07
M,114,S,35,50.18
A,140,S,35,50.19
A,141,S,60,50.16
A,142,S,75,50.18
A,143,B,48,50.14
A,144,B,27,50.19
T,14,50.15
T,13,50.15
A,145,S,54,50.20
A,146,B,9,50.15
T,9,50.15
X,80,B,97,50.10
A,147,B,97,50.17
T,14,50.15
T,31,50.15
T,3,50.16
T,49,50.16
M,143,B,96,50.14
A,148,S,29,50.21
X,143,B,96,50.14
A,149,S,100,50.17
A,150,S,38,50.17
A,151,S,31,50.18
A,152,B,64,50.13
A,153,B,59,50.15
X,153,B,59,50.15
A,154,B,80,50.18
T,26,50.16
T,54,50.16
A,155,B,50,50.18
T,35,50.16
T,15,50.16
X,103,B,44,50.12
A,156,S,81,50.21
A,157,B,43,50.18
T,43,50.16
A,158,S,72,50.17
A,159,B,7,50.15
A,160,S,77,50.20
A,136,S,76,1.999
A,161,B,20,50.16
A,TVeQbPnEfY,B,10,1234
T,9,50.16
T,11,50.16
A,162,S,94,50.18
A,163,S,81,50.20
A,164,B,99,50.19
T,16,50.16
T,83,50.16
M,145,S,54,50.21
A,165,S,11,50.19
X,106,S,3,50.18
A,166,B,51,50.18
T,3,50.16
T,48,50.16
A,167,S,47,50.19
A,168,S,79,50.18
A,169,B,55,50.18
T,15,50.16
T,40,50.16
M,122,S,70,50.19
M,0,B,45.28,473.00
T,504,1562.01
A,170,S,91,50.20
A,171,B,89,50.19
T,20,50.16
T,58,50.16
T,11,50.16
X,135,S,78,50.19
A,172,S,19,50.19
A,173,S,63,50.21
X,142,S,75,50.18
X,151,S,31,50.18
A,174,B,83,50.18
T,39,50.16
T,44,50.16
X,159,B,7,50.15
A,175,B,7,50.16
T,7,50.16
X,138,S,30,50.16
A,176,B,5,50.14
M,176,B,2,50.14
A,177,B,89,50.16
T,31,50.16
T,58,50.16
A,178,B,15,50.17
T,15,50.16
M,176,B,2,50.14
M,152,B,62,50.13
M,176,B,2,50.12
X,152,B,62,50.13
A,179,S,97,50.17
A,180,S,43,50.18
X,165,S,11,50.19
A,181,S,3,50.19
X,179,S,97,50.17
A,182,S,23,50.20
M,128,S,82,50.18
A,183,B,87,50.14
A,184,S,71,50.17
A,185,B,73,50.19
T,11,50.16
T,60,50.16
T,2,50.17
A,186,B,18,50.18
T,18,50.17
A,187,S,28,50.22
X,183,B,87,50.14
A,188,B,32,50.14
M,182,S,23,50.17
A,189,B,59,50.18
T,59,50.17
A,190,S,68,50.22
X,176,B,2,50.12
A,191,B,23,50.15
A,192,B,20,50.16
A,193,B,28,50.17
T,11,50.17
T,17,50.17
M,150,S,61,50.17
X,172,S,19,50.19
A,194,B,24,50.17
T,24,50.17
M,188,B,25,50.14
X,182,S,23,50.17
A,195,S,18,50.20
A,196,B,61,50.17
T,59,50.17
T,2,50.17
A,197,B,26,50.17
T,26,50.17
A,198,S,89,50.21
A,199,B,65,50.21
T,44,50.17
T,21,50.17
M,188,B,27,50.14
A,200,B,91,50.20
T,50,50.17
T,41,50.17
A,201,B,12,50.21
T,12,50.17
A,202,S,2,50.20
X,168,S,79,50.18
A,203,B,9,50.18
T,8,50.17
T,1,50.18
M,188,B,37,50.14
A,204,B,45,50.18
T,3,50.18
T,42,50.18
A,205,B,33,50.21
T,33,50.18
M,198,S,26,50.21
A,206,B,13,50.18
T,13,50.18
X,188,B,37,50.14
A,207,S,57,50.20
A,208,S,92,50.19
M,192,B,30,50.16
A,209,B,59,50.20
T,9,50.18
T,30,50.18
T,20,50.18
A,210,B,42,50.20
T,15,50.18
T,27,50.18
X,122,S,70,50.19
A,211,S,77,50.22
X,156,S,81,50.21
X,202,S,2,50.20
A,212,B,20,50.18
T,20,50.18
A,213,S,43,50.19
M,191,B,17,50.15
A,214,B,26,50.21
T,26,50.18
A,215,S,16,50.20
X,191,B,17,50.15
M,187,S,14,50.22
A,216,S,70,50.22
A,217,S,75,50.22
A,218,S,15,50.22
A,219,B,19,50.19
T,9,50.18
T,10,50.18
X,218,S,15,50.22
A,220,S,67,50.19
A,221,B,50,50.19
T,152,5249.01
T,50,50.18
A,222,B,78,50.18
T,34,50.18
T,43,50.18
A,223,S,74,50.20
M,192,B,56,50.16
A,224,S,100,50.23
A,225,B,41,50.23
T,23,50.19
T,18,50.19
M,223,S,110,50.20
X,216,S,70,50.22
A,226,B,62,50.19
T,17,50.19
T,45,50.19
A,227,B,60,50.20
T,2,50.19
T,3,50.19
T,55,50.19
A,228,S,9,50.24
A,229,B,9,50.23
T,9,50.19
A,230,S,54,50.22
A,-98,B,10,1234
A,231,S,54,50.24
M,222,B,2,50.18
A,232,S,21,50.22
A,233,S,38,50.21
A,234,B,71,50.19
T,28,50.19
T,43,50.19
A,235,B,53,50.22
T,53,50.19
A,236,S,17,50.24
A,237,B,83,50.22
T,14,50.19
T,69,50.20
A,238,B,54,50.20
A,192,B,83,1.164
T,8,50.20
T,46,50.20
A,239,B,24,50.20
T,24,50.20
A,240,B,12,50.21
T,11,50.20
T,1,50.20
A,241,S,67,50.15
T,2,50.15
T,56,50.15
A,242,S,48,50.19
A,243,S,50,50.18
A,244,S,47,50.20
A,245,S,15,50.19
A,246,S,44,50.19
A,247,S,26,50.16
A,248,S,19,50.17
A,249,S,96,50.20
A,250,B,7,50.02
A,251,S,14,50.18
A,252,S,82,50.17
A,253,S,60,50.19
A,254,S,70,50.16
A,255,S,32,50.18
X,250,B,7,50.02
A,256,B,9,50.03
M,256,B,5,50.03
M,211,S,7,50.22
A,257,B,73,50.04
A,258,B,34,50.08
A,259,S,35,50.19
A,260,B,79,50.11
X,260,B,79,50.11
X,256,B,5,50.03
A,261,B,94,50.11
A,262,B,28,50.15
T,9,50.15
A,263,S,33,50.18
